<?xml version="1.0" ?>
<sdf version="1.5">
  <model name="turtlebot3_burger">
    <pose>0.0 0.0 0.0 0.0 0.0 0.0</pose>
    <link name="base_footprint"/>
    <link name="base_link">
      <inertial>
        <pose>-0.064 0 0.070 0 0 0</pose>
        <inertia><ixx>1.95e-02</ixx><ixy>0</ixy><ixz>0</ixz><iyy>1.95e-02</iyy><iyz>0</iyz><izz>1.95e-02</izz></inertia>
        <mass>0.825</mass>
      </inertial>
      <collision name="base_collision">
        <pose>-0.032 0 0.070 0 0 0</pose>
        <geometry><box><size>0.14 0.14 0.14</size></box></geometry>
      </collision>
      <visual name="base_visual">
        <pose>-0.032 0 0 0 0 0</pose>
        <geometry>
          <mesh><uri>model://turtlebot3_common/meshes/bases/burger_base.stl</uri><scale>0.001 0.001 0.001</scale></mesh>
        </geometry>
        <material><ambient>0.3 0.3 0.3 1.0</ambient><diffuse>0.3 0.3 0.3 1.0</diffuse></material>
      </visual>
      <!-- CUSTOM ARUCO MARKER PLATE -->
      <visual name="aruco_visual">
        <pose>0 0 0.2 0 0 0</pose> <!-- Positioned 20cm up (above LIDAR) -->
        <geometry><box><size>0.5 0.5 0.001</size></box></geometry> <!-- 50cm x 50cm Plate -->
        <material>
          <ambient>1 1 1 1</ambient><diffuse>1 1 1 1</diffuse><specular>0 0 0 1</specular>
          <pbr><metal>
              <albedo_map>model://turtlebot3_burger_aruco/materials/textures/aruco_marker_0.png</albedo_map>
          </metal></pbr>
        </material>
      </visual>
    </link>
    <link name="imu_link">
      <sensor name="tb3_imu" type="imu">
        <always_on>true</always_on><update_rate>200</update_rate><topic>imu</topic>
        <pose>-0.032 0 0.068 0 0 0</pose>
      </sensor>
    </link>
    <link name="base_scan">
      <inertial><pose>-0.02 0 0.161 0 0 0</pose><inertia><ixx>0.001</ixx><ixy>0</ixy><ixz>0</ixz><iyy>0.001</iyy><iyz>0</iyz><izz>0.001</izz></inertia><mass>0.114</mass></inertial>
      <collision name="lidar_sensor_collision">
        <pose>-0.02 0 0.161 0 0 0</pose>
        <geometry><cylinder><radius>0.05</radius><length>0.055</length></cylinder></geometry>
      </collision>
      <visual name="lidar_sensor_visual">
        <pose>-0.032 0 0.171 0 0 0</pose>
        <geometry><mesh><uri>model://turtlebot3_common/meshes/sensors/lds.stl</uri><scale>0.001 0.001 0.001</scale></mesh></geometry>
        <material><ambient>0.2 0.2 0.2 1.0</ambient><diffuse>0.2 0.2 0.2 1.0</diffuse></material>
      </visual>
      <sensor name="hls_lfcd_lds" type="gpu_lidar">
        <always_on>true</always_on><visualize>true</visualize><pose>-0.032 0 0.171 0 0 0</pose><topic>scan</topic><gz_frame_id>base_scan</gz_frame_id>
        <lidar><scan><horizontal><samples>360</samples><resolution>1</resolution><min_angle>0</min_angle><max_angle>6.28</max_angle></horizontal></scan><range><min>0.12</min><max>3.5</max></range></lidar>
      </sensor>
    </link>
    <link name="wheel_left_link">
      <inertial><pose>0 0.08 0.023 -1.57 0 0</pose><inertia><ixx>1.11e-05</ixx><ixy>0</ixy><ixz>0</ixz><iyy>1.11e-05</iyy><iyz>0</iyz><izz>2.07e-05</izz></inertia><mass>0.028</mass></inertial>
      <collision name="wheel_left_collision"><pose>0 0.08 0.023 -1.57 0 0</pose><geometry><cylinder><radius>0.033</radius><length>0.018</length></cylinder></geometry><surface><friction><ode><mu>1000</mu><mu2>1000</mu2></ode></friction></surface></collision>
      <visual name="wheel_left_visual"><pose>0 0.08 0.023 0 0 0</pose><geometry><mesh><uri>model://turtlebot3_common/meshes/wheels/left_tire.stl</uri><scale>0.001 0.001 0.001</scale></mesh></geometry><material><ambient>0.2 0.2 0.2 1</ambient><diffuse>0.2 0.2 0.2 1</diffuse></material></visual>
    </link>
    <link name="wheel_right_link">
      <inertial><pose>0 -0.08 0.023 -1.57 0 0</pose><inertia><ixx>1.11e-05</ixx><ixy>0</ixy><ixz>0</ixz><iyy>1.11e-05</iyy><iyz>0</iyz><izz>2.07e-05</izz></inertia><mass>0.028</mass></inertial>
      <collision name="wheel_right_collision"><pose>0 -0.08 0.023 -1.57 0 0</pose><geometry><cylinder><radius>0.033</radius><length>0.018</length></cylinder></geometry><surface><friction><ode><mu>1000</mu><mu2>1000</mu2></ode></friction></surface></collision>
      <visual name="wheel_right_visual"><pose>0 -0.08 0.023 0 0 0</pose><geometry><mesh><uri>model://turtlebot3_common/meshes/wheels/right_tire.stl</uri><scale>0.001 0.001 0.001</scale></mesh></geometry><material><ambient>0.2 0.2 0.2 1</ambient><diffuse>0.2 0.2 0.2 1</diffuse></material></visual>
    </link>
    <link name='caster_back_link'>
      <pose>-0.081 0 -0.004 -1.57 0 0</pose>
      <inertial><mass>0.005</mass><inertia><ixx>0.001</ixx><ixy>0</ixy><ixz>0</ixz><iyy>0.001</iyy><iyz>0</iyz><izz>0.001</izz></inertia></inertial>
      <collision name='collision'><geometry><sphere><radius>0.005</radius></sphere></geometry><surface><contact><ode><soft_cfm>0</soft_cfm><soft_erp>0.2</soft_erp><kp>1e+5</kp><kd>1</kd></ode></contact></surface></collision>
    </link>
    <joint name="base_joint" type="fixed"><parent>base_footprint</parent><child>base_link</child><pose>0.0 0.0 0.010 0 0 0</pose></joint>
    <joint name="wheel_left_joint" type="revolute"><parent>base_link</parent><child>wheel_left_link</child><pose>0.0 0.08 0.023 -1.57 0 0</pose><axis><xyz>0 0 1</xyz></axis></joint>
    <joint name="wheel_right_joint" type="revolute"><parent>base_link</parent><child>wheel_right_link</child><pose>0.0 -0.08 0.023 -1.57 0 0</pose><axis><xyz>0 0 1</xyz></axis></joint>
    <joint name='caster_back_joint' type='ball'><parent>base_link</parent><child>caster_back_link</child></joint>
    <joint name="imu_joint" type="fixed"><parent>base_link</parent><child>imu_link</child><pose>-0.032 0 0.068 0 0 0</pose><axis><xyz>0 0 1</xyz></axis></joint>
    <joint name="lidar_joint" type="fixed"><parent>base_link</parent><child>base_scan</child><pose>-0.032 0 0.171 0 0 0</pose><axis><xyz>0 0 1</xyz></axis></joint>
    <plugin filename="gz-sim-diff-drive-system" name="gz::sim::systems::DiffDrive">
      <left_joint>wheel_left_joint</left_joint><right_joint>wheel_right_joint</right_joint>
      <wheel_separation>0.160</wheel_separation><wheel_radius>0.033</wheel_radius>
      <max_linear_acceleration>1.0</max_linear_acceleration>
      <topic>/cmd_vel</topic>
      <odom_topic>odom</odom_topic><frame_id>odom</frame_id><child_frame_id>base_footprint</child_frame_id>
      <tf_topic>/tf</tf_topic>
    </plugin>
    <plugin filename="gz-sim-joint-state-publisher-system" name="gz::sim::systems::JointStatePublisher">
      <topic>joint_states</topic><joint_name>wheel_left_joint</joint_name><joint_name>wheel_right_joint</joint_name>
    </plugin>
  </model>
</sdf>
